Workbook

Sheet Sheet1
A1: MDA'S MOTOR-VEHICLE DEDUCTION RETURNS AS AT APRIL, 2020.
A2: S/N | B2: REF. I.D | C2: STAFF NAME | D2: PRINCIPAL N | E2: INTEREST N | F2: TOTAL LOAN N | G2: NO. OF. INSTL. | H2: MONTHLY DED N | I2: MONTHLY INTEREST | J2: MONTHLY PRINCIPAL | K2: TOTAL INTEREST PAID | L2: TOTAL OUTSTANDING INTEREST | M2: NO. OF INSTAL. PAID | N2: NO. OF INSTAL. OUTS. | O2: TOTAL LOAN PAID N | P2: OUTS. BAL. N | Q2: REMARK | S2: NO. OF INSTAL. PAID | T2: NO. OF INSTAL. OUTS. | U2: TOTAL LOAN PAID N | V2: OUTS. BAL. N
A3: 1 | B3: 0 | C3: MR. A. A. OLADOJA | D3: 500000 | E3: =D3*0.1333 -> 66650 | F3: =D3+E3 -> 566650 | G3: 50 | H3: 11333 | I3: =E3/G3 -> 1333 | J3: =D3/G3 -> 10000 | K3: =M3*I3 -> 17329 | L3: =I3*N3 -> 49321 | M3: =S3+R3 -> 13 | N3: =T3-R3 -> 37 | O3: =U3+H3 -> 147328 | P3: =V3-H3 -> 407988 | R3: 1 | S3: 12 | T3: 38 | U3: 135995 | V3: 419321 | Z3: ACCOUNT
A4: 2 | B4: 0 | C4: ADENUGA JUMOKE A. | D4: 600000 | E4: =D4*0.1333 -> 79980 | F4: =D4+E4 -> 679980 | G4: 50 | H4: 13333 | I4: =E4/G4 -> 1599.6 | J4: =D4/G4 -> 12000 | K4: =M4*I4 -> 70382.4 | L4: =I4*N4 -> 11197.2 | M4: =S4+R4 -> 44 | N4: =T4-R4 -> 7 | O4: =U4+H4 -> 327483.76 | P4: =V4-H4 -> 639984 | R4: 1 | S4: 43 | T4: 8 | U4: 314150.76 | V4: 653317 | Y4: 12034.94
A5: 3 | B5: 0 | C5: ALABI FUNMILAYO S. | D5: 330000 | E5: =D5*0.1333 -> 43989 | F5: =D5+E5 -> 373989 | G5: 50 | H5: 7479.78 | I5: =E5/G5 -> 879.78 | J5: =D5/G5 -> 6600 | K5: =M5*I5 -> 44868.78 | L5: =I5*N5 -> 0 | M5: =S5+R5 -> 51 | N5: =T5-R5 -> 0 | O5: =U5+H5 -> 329110.32 | P5: =V5-H5 -> 44878.68 | R5: 1 | S5: 50 | T5: 1 | U5: 321630.54 | V5: 52358.46
A6: 4 | B6: 0 | C6: MR. OLUSEYE ABODERIN | D6: 450000 | E6: =D6*0.1333 -> 59985 | F6: =D6+E6 -> 509985 | G6: 50 | H6: 10199.7 | I6: =E6/G6 -> 1199.7 | J6: =D6/G6 -> 9000 | K6: =M6*I6 -> 19195.2 | L6: =I6*N6 -> 40789.8 | M6: =S6+R6 -> 16 | N6: =T6-R6 -> 34 | O6: =U6+H6 -> 173394.9 | P6: =V6-H6 -> 346789.8 | R6: 1 | S6: 15 | T6: 35 | U6: 163195.2 | V6: 356989.5
A7: 5 | C7: MRS. A. B. FOLAHAN | D7: 150000 | E7: =D7*0.1333 -> 19995 | F7: =D7+E7 -> 169995 | G7: 50 | H7: 3399.9 | I7: =E7/G7 -> 399.9 | J7: =D7/G7 -> 3000 | K7: =M7*I7 -> 4798.8 | L7: =I7*N7 -> 15196.2 | M7: =S7+R7 -> 12 | N7: =T7-R7 -> 38 | O7: =U7+H7 -> 40798.8 | P7: =V7-H7 -> 129196.2 | R7: 1 | S7: 11 | T7: 39 | U7: 37398.9 | V7: 132596.1 | X7: =SUM(H3:H7) -> 45745.38 | AD7: 0
A8: 6 | B8: 0 | C8: MR. I. J. OLAGUNJU | D8: 330000 | E8: =D8*0.1333 -> 43989 | F8: =D8+E8 -> 373989 | G8: 50 | H8: 7479.78 | I8: =E8/G8 -> 879.78 | J8: =D8/G8 -> 6600 | K8: =M8*I8 -> 35191.2 | L8: =I8*N8 -> 9677.58 | M8: =S8+R8 -> 40 | N8: =T8-R8 -> 11 | O8: =U8+H8 -> 291711.42 | P8: =V8-H8 -> 82277.58 | R8: 1 | S8: 39 | T8: 12 | U8: 284231.64 | V8: 89757.36 | Z8: APPEAL
A9: 7 | C9: MRS. B. O. SOMIDE | D9: 450000 | E9: =D9*0.1333 -> 59985 | F9: =D9+E9 -> 509985 | G9: 50 | H9: 10199.7 | I9: =E9/G9 -> 1199.7 | J9: =D9/G9 -> 9000 | K9: =M9*I9 -> 5998.5 | L9: =I9*N9 -> 53986.5 | M9: =S9+R9 -> 5 | N9: =T9-R9 -> 45 | O9: =U9+H9 -> 50998.5 | P9: =V9-H9 -> 458986.5 | R9: 1 | S9: 4 | T9: 46 | U9: 40798.8 | V9: 469186.2
A10: 8 | C10: MRS O.F. STANLEY JOHN | D10: 450000 | E10: =D10*0.1333 -> 59985 | F10: =D10+E10 -> 509985 | G10: 50 | H10: 13699.7 | I10: =E10/G10 -> 1199.7 | J10: =D10/G10 -> 9000 | K10: =M10*I10 -> 2399.4 | L10: =I10*N10 -> 57585.6 | M10: =S10+R10 -> 2 | N10: =T10-R10 -> 48 | O10: =U10+H10 -> 27399.4 | P10: =V10-H10 -> 482585.6 | R10: 1 | S10: 1 | T10: 49 | U10: 13699.7 | V10: 496285.3 | X10: =SUM(H8:H10) -> 31379.18
A11: 9 | C11: MRS ADEYEYE-KUKU O.O | D11: 450000 | E11: =D11*0.1333 -> 59985 | F11: =D11+E11 -> 509985 | G11: 50 | H11: 9999.75 | I11: =E11/G11 -> 1199.7 | J11: =D11/G11 -> 9000 | K11: =M11*I11 -> 3599.1 | L11: =I11*N11 -> 56385.9 | M11: =S11+R11 -> 3 | N11: =T11-R11 -> 47 | O11: =U11+H11 -> 19999.5 | P11: 489987.75 | R11: 1 | S11: 2 | T11: 48 | U11: 9999.75 | V11: 489987.75 | Z11: AUDIT
A12: 10 | C12: MR. J. O. AWOTUNDE | D12: 330000 | E12: =D12*0.13333 -> 43998.9 | F12: =D12+E12 -> 373998.9 | G12: 37 | H12: 10000 | I12: =E12/G12 -> 1189.1595 | J12: =D12/G12 -> 8918.9189 | K12: =M12*I12 -> 8324.1162 | L12: =I12*N12 -> 51133.857 | M12: =S12+R12 -> 7 | N12: =T12-R12 -> 43 | O12: =U12+H12 -> 70000 | P12: =V12-H12 -> 303998.9 | R12: 1 | S12: 6 | T12: 44 | U12: 60000 | V12: 313998.9
A13: 11 | C13: MR. J. B. AYANKOSO | D13: 500000 | E13: =D13*0.13333 -> 66665 | F13: =D13+E13 -> 566665 | G13: 50 | H13: 11333 | I13: =E13/G13 -> 1333.3 | J13: =D13/G13 -> 10000 | K13: =M13*I13 -> 6666.5 | L13: =I13*N13 -> 59998.5 | M13: =S13+R13 -> 5 | N13: =T13-R13 -> 45 | O13: =U13+H13 -> 56665 | P13: =V13-H13 -> 510000 | R13: 1 | S13: 4 | T13: 46 | U13: 45332 | V13: 521333 | X13: =SUM(H11:H13) -> 31332.75
A14: 12 | B14: 0 | C14: OLASUNKANMI A. | D14: 450000 | E14: =D14*0.1333 -> 59985 | F14: =G14*H14 -> 509985 | G14: 50 | H14: 10199.7 | I14: =E14/G14 -> 1199.7 | J14: =D14/G14 -> 9000 | K14: =M14*I14 -> 61184.7 | L14: =I14*N14 -> 0 | M14: =S14+R14 -> 51 | N14: =T14-R14 -> 0 | O14: =U14+H14 -> 438587.1 | P14: =V14-H14 -> 71397.9 | R14: 1 | S14: 50 | T14: 1 | U14: 428387.4 | V14: 81597.6
A15: 13 | B15: 0 | C15: O. M. AKINLABI | D15: 150000 | E15: =D15*0.1333 -> 19995 | F15: =G15*H15 -> 169995 | G15: 50 | H15: 3399.9 | I15: =E15/G15 -> 399.9 | J15: =D15/G15 -> 3000 | K15: =M15*I15 -> 7598.1 | L15: =I15*N15 -> 12396.9 | M15: =S15+R15 -> 19 | N15: =T15-R15 -> 31 | O15: =U15+H15 -> 101994.3 | P15: =V15-H15 -> 68000.7 | R15: 1 | S15: 18 | T15: 32 | U15: 98594.4 | V15: 71400.6
A16: 14 | B16: 0 | C16: MR. OTITOLOJU O. ADISA | D16: 500000 | E16: =D16*0.1333 -> 66650 | F16: =G16*H16 -> 566650 | G16: 50 | H16: 11333 | I16: =E16/G16 -> 1333 | J16: =D16/G16 -> 10000 | K16: =M16*I16 -> 23994 | L16: =I16*N16 -> 42656 | M16: =S16+R16 -> 18 | N16: =T16-R16 -> 32 | O16: =U16+H16 -> 203994 | P16: =V16-H16 -> 362656 | R16: 1 | S16: 17 | T16: 33 | U16: 192661 | V16: 373989
A17: 15 | B17: 0 | C17: MRS. ADEUGA M.M. | D17: 500000 | E17: =D17*0.09 -> 45000 | F17: =G17*H17 -> 566650 | G17: 50 | H17: 11333 | I17: =E17/G17 -> 900 | J17: =D17/G17 -> 10000 | K17: =M17*I17 -> 16200 | L17: =I17*N17 -> 28800 | M17: =S17+R17 -> 18 | N17: =T17-R17 -> 32 | O17: =U17+H17 -> 203994 | P17: =V17-H17 -> 362656 | R17: 1 | S17: 17 | T17: 33 | U17: 192661 | V17: 373989
A18: 16 | B18: 0 | C18: MR. NASIRU A | D18: 330000 | E18: =D18*0.09 -> 29700 | F18: =G18*H18 -> 373989 | G18: 50 | H18: 7479.78 | I18: =E18/G18 -> 594 | J18: =D18/G18 -> 6600 | K18: =M18*I18 -> 10692 | L18: =I18*N18 -> 19008 | M18: =S18+R18 -> 18 | N18: =T18-R18 -> 32 | O18: =U18+H18 -> 134636.04 | P18: =V18-H18 -> 239352.96 | R18: 1 | S18: 17 | T18: 33 | U18: 127156.26 | V18: 246832.74
A19: 17 | C19: MISS. T. A. ADESOLA | D19: 450000 | E19: =D19*0.09 -> 40500 | F19: =G19*H19 -> 478800 | G19: 24 | H19: 19950 | I19: =E19/G19 -> 1687.5 | J19: =D19/G19 -> 18750 | K19: =M19*I19 -> 15187.5 | L19: =I19*N19 -> 69187.5 | M19: =S19+R19 -> 9 | N19: =T19-R19 -> 41 | O19: =U19+H19 -> 179550 | P19: =V19-H19 -> 299250 | R19: 1 | S19: 8 | T19: 42 | U19: 159600 | V19: 319200 | W19: CR'S
A20: 18 | C20: MRS. PATRICIA ADETUYIBI | D20: 500000 | E20: =D20*0.09 -> 45000 | F20: =G20*H20 -> 566650 | G20: 50 | H20: 11333 | I20: =E20/G20 -> 900 | J20: =D20/G20 -> 10000 | K20: =M20*I20 -> 11700 | L20: =I20*N20 -> 33300 | M20: =S20+R20 -> 13 | N20: =T20-R20 -> 37 | O20: =U20+H20 -> 147329 | P20: =V20-H20 -> 419321 | R20: 1 | S20: 12 | T20: 38 | U20: 135996 | V20: 430654
A21: 19 | C21: MRS. O. A. AKANDE | D21: 150000 | E21: =D21*0.09 -> 13500 | F21: =G21*H21 -> 169995 | G21: 50 | H21: 3399.9 | I21: =E21/G21 -> 270 | J21: =D21/G21 -> 3000 | K21: =M21*I21 -> 3240 | L21: =I21*N21 -> 10260 | M21: =S21+R21 -> 12 | N21: =T21-R21 -> 38 | O21: =U21+H21 -> 40798.8 | P21: =V21-H21 -> 129196.2 | R21: 1 | S21: 11 | T21: 39 | U21: 37398.9 | V21: 132596.1
A22: 20 | C22: MRS ADEROUNMU | D22: 500000 | E22: =D22*0.1333 -> 66650 | F22: =G22*H22 -> 527191.92 | G22: 24 | H22: 21966.33 | I22: =E22/G22 -> 2777.0833 | J22: =D22/G22 -> 20833.333 | K22: =M22*I22 -> 5554.1667 | L22: =I22*N22 -> 61095.833 | M22: =S22+R22 -> 2 | N22: =T22-R22 -> 22 | O22: =U22+H22 -> 43932.66 | P22: =V22-H22 -> 483259.34 | R22: 1 | S22: 1 | T22: 23 | U22: 21966.33 | V22: 505225.67
A23: 21 | C23: MR SHOMOYE T.H. | D23: 500000 | E23: =D23*0.1333 -> 66650 | F23: =G23*H23 -> 509985 | G23: 50 | H23: 10199.7 | I23: =E23/G23 -> 1333 | J23: =D23/G23 -> 10000 | K23: =M23*I23 -> 3999 | L23: =I23*N23 -> 63984 | M23: =S23+R23 -> 3 | N23: =T23-R23 -> 48 | O23: =U23+H23 -> 20399.4 | P23: =V23-H23 -> 495025.97 | R23: 1 | S23: 2 | T23: 49 | U23: 10199.7 | V23: 505225.67
A24: 22 | C24: MRS O.O ADENUGA | D24: 500000 | E24: =D24*0.1333 -> 66650 | F24: =G24*H24 -> 509985 | G24: 50 | H24: 10199.7 | I24: =E24/G24 -> 1333 | J24: =D24/G24 -> 10000 | K24: =M24*I24 -> 3999 | L24: =I24*N24 -> 63984 | M24: =S24+R24 -> 3 | N24: =T24-R24 -> 48 | O24: =U24+H24 -> 20399.4 | P24: 499785.3 | R24: 1 | S24: 2 | T24: 49 | U24: 10199.7 | V24: 505225.67
A25: 23 | C25: MISS A.O. ALIMI | D25: 500000 | E25: =D25*0.1333 -> 66650 | F25: =G25*H25 -> 684985 | G25: 50 | H25: 13699.7 | I25: =E25/G25 -> 1333 | J25: =D25/G25 -> 10000 | K25: =M25*I25 -> 3999 | L25: =I25*N25 -> 65317 | M25: =S25+R25 -> 3 | N25: 49 | O25: =U25+H25 -> 27399.4 | P25: =V25-H25 -> 491525.97 | R25: 1 | S25: 2 | T25: 49 | U25: 13699.7 | V25: 505225.67
A26: 24 | C26: FAMOKUN M.O. | D26: 500000 | E26: 66650 | F26: 509985 | G26: 50 | H26: 10199.7 | I26: 1333 | J26: 10000 | K26: 3999 | L26: 65317 | M26: 3 | N26: 49 | O26: 20399.4 | P26: 505225.67 | R26: 1 | S26: 2 | T26: 49 | U26: 10199.7 | V26: 505225.67 | X26: =SUM(H14:H26) -> 144693.41
A27: 25 | B27: 0 | C27: OLUSANYA FLORENCE O. | D27: 450000 | E27: =D27*0.1333 -> 59985 | F27: =G27*H27 -> 509985 | G27: 50 | H27: 10199.7 | I27: =E27/G27 -> 1199.7 | J27: =D27/G27 -> 9000 | K27: =M27*I27 -> 52786.8 | L27: =I27*N27 -> 8397.9 | M27: =S27+R27 -> 44 | N27: =T27-R27 -> 7 | O27: =U27+H27 -> 438687.1 | P27: =V27-H27 -> 71297.9 | R27: 1 | S27: 43 | T27: 8 | U27: 428487.4 | V27: 81497.6 | Z27: ESTAB
A28: 26 | B28: 0 | C28: OLAWORE MICHEAL F. | D28: 330000 | E28: =D28*0.1333 -> 43989 | F28: =G28*H28 -> 373989 | G28: 50 | H28: 7479.78 | I28: =E28/G28 -> 879.78 | J28: =D28/G28 -> 6600 | K28: =M28*I28 -> 38710.32 | L28: =I28*N28 -> 6158.46 | M28: =S28+R28 -> 44 | N28: =T28-R28 -> 7 | O28: =U28+H28 -> 321630.54 | P28: =V28-H28 -> 52358.46 | R28: 1 | S28: 43 | T28: 8 | U28: 314150.76 | V28: 59838.24
A29: 27 | C29: MRS. TAIWO O. ADEJUMO | D29: 330000 | E29: =D29*0.1333 -> 43989 | F29: =G29*H29 -> 373989 | G29: 50 | H29: 7479.78 | I29: =E29/G29 -> 879.78 | J29: =D29/G29 -> 6600 | K29: =M29*I29 -> 15836.04 | L29: =I29*N29 -> 28152.96 | M29: =S29+R29 -> 18 | N29: =T29-R29 -> 32 | O29: =U29+H29 -> 134636.04 | P29: =V29-H29 -> 239352.96 | R29: 1 | S29: 17 | T29: 33 | U29: 127156.26 | V29: 246832.74
A30: 28 | B30: 0 | C30: MRS. T. A. MOJEED | D30: 130000 | E30: =D30*0.1333 -> 17329 | F30: =G30*H30 -> 169995 | G30: 50 | H30: 3399.9 | I30: =E30/G30 -> 346.58 | J30: =D30/G30 -> 2600 | K30: =M30*I30 -> 346.58 | L30: =I30*N30 -> 16982.42 | M30: 1 | N30: 49 | O30: =U30+H30 -> 282191.7 | P30: =V30-H30 -> 64598.1 | R30: 1 | S30: 1 | T30: 49 | U30: 278791.8 | V30: 67998
A31: 29 | B31: 0 | C31: MR. KEHINDE ADEOSUN | D31: 450000 | E31: =D31*0.1333 -> 59985 | F31: =G31*H31 -> 509985 | G31: 50 | H31: 10199.7 | I31: =E31/G31 -> 1199.7 | J31: =D31/G31 -> 9000 | K31: =M31*I31 -> 20394.9 | L31: =I31*N31 -> 39590.1 | M31: =S31+R31 -> 17 | N31: =T31-R31 -> 33 | O31: =U31+H31 -> 173394.9 | P31: =V31-H31 -> 336590.1 | R31: 1 | S31: 16 | T31: 34 | U31: 163195.2 | V31: 346789.8
A32: 30 | C32: MRS. O. A. IDOWU | D32: 330000 | E32: =D32*0.1333 -> 43989 | F32: =G32*H32 -> 373989 | G32: 50 | H32: 7479.78 | I32: =E32/G32 -> 879.78 | J32: =D32/G32 -> 6600 | K32: =M32*I32 -> 4398.9 | L32: =I32*N32 -> 39590.1 | M32: =S32+R32 -> 5 | N32: =T32-R32 -> 45 | O32: =U32+H32 -> 37398.9 | P32: =V32-H32 -> 336590.1 | R32: 1 | S32: 4 | T32: 46 | U32: 29919.12 | V32: 344069.88
A33: 31 | C33: MRS O.T. ADESINA | D33: 330000 | E33: =D33*0.1333 -> 43989 | F33: =G33*H33 -> 373989 | G33: 50 | H33: 7479.78 | I33: =E33/G33 -> 879.78 | J33: =D33/G33 -> 6600 | K33: =M33*I33 -> 879.78 | L33: =I33*N33 -> 43109.22 | M33: 1 | N33: 49 | O33: =U33+H33 -> 14959.56 | P33: =V33-H33 -> 351549.66 | R33: 1 | S33: 1 | T33: 49 | U33: 7479.78 | V33: 359029.44 | X33: =SUM(H27:H33) -> 53718.42
A34: 32 | B34: 0 | C34: AKINYELE A. A.O. | D34: 500000 | E34: =D34*0.1333 -> 66650 | F34: =G34*H34 -> 400000 | G34: 50 | H34: 8000 | I34: =E34/G34 -> 1333 | J34: =D34/G34 -> 10000 | K34: =M34*I34 -> 67983 | L34: =I34*N34 -> 0 | M34: =S34+R34 -> 51 | N34: =T34-R34 -> 0 | O34: =U34+H34 -> 495319 | P34: =V34-H34 -> 71331 | R34: 1 | S34: 50 | T34: 1 | U34: 487319 | V34: 79331 | Z34: G40
A35: 33 | C35: MRS. M. A. BAMIRO | D35: 500000 | E35: =D35*0.1333 -> 66650 | F35: =G35*H35 -> 547984.8 | G35: 36 | H35: 15221.8 | I35: =E35/G35 -> 1851.3889 | J35: =D35/G35 -> 13888.889 | K35: =M35*I35 -> 24068.056 | L35: =I35*N35 -> 42581.944 | M35: =S35+R35 -> 13 | N35: =T35-R35 -> 23 | O35: =U35+H35 -> 197883.4 | P35: =V35-H35 -> 350101.4 | R35: 1 | S35: 12 | T35: 24 | U35: 182661.6 | V35: 365323.2
A36: 34 | C36: MRS. B.S. ODEMAKINDE | D36: 500000 | E36: =D36*0.1333 -> 66650 | F36: =G36*H36 -> 708312.5 | G36: 50 | H36: 14166.25 | I36: =E36/G36 -> 1333 | J36: =D36/G36 -> 10000 | K36: =M36*I36 -> 29326 | L36: =I36*N36 -> 37324 | M36: =S36+R36 -> 22 | N36: =T36-R36 -> 28 | O36: =U36+H36 -> 252159.25 | P36: =V36-H36 -> 314490.75 | R36: 1 | S36: 21 | T36: 29 | U36: 237993 | V36: 328657
A37: 35 | C37: MR. MARTINS K. O. | D37: 450000 | E37: =D37*0.1333 -> 59985 | F37: =G37*H37 -> 509985 | G37: 50 | H37: 10199.7 | I37: =E37/G37 -> 1199.7 | J37: =D37/G37 -> 9000 | K37: =M37*I37 -> 19195.2 | L37: =I37*N37 -> 40789.8 | M37: =S37+R37 -> 16 | N37: =T37-R37 -> 34 | O37: =U37+H37 -> 173394.9 | P37: =V37-H37 -> 346789.8 | R37: 1 | S37: 15 | T37: 35 | U37: 163195.2 | V37: 356989.5
A38: 36 | B38: 0 | C38: ADEBOYA O. O. | D38: 450000 | E38: =D38*0.1333 -> 59985 | F38: =G38*H38 -> 509985 | G38: 50 | H38: 10199.7 | I38: =E38/G38 -> 1199.7 | J38: =D38/G38 -> 9000 | K38: =M38*I38 -> 34791.3 | L38: =I38*N38 -> 25193.7 | M38: =S38+R38 -> 29 | N38: =T38-R38 -> 21 | O38: =U38+H38 -> 295791.3 | P38: =V38-H38 -> 214193.7 | R38: 1 | S38: 28 | T38: 22 | U38: 285591.6 | V38: 224393.4
A39: 37 | B39: 0 | C39: MRS D.I KOMOLAFE | D39: 450000 | E39: =D39*0.1333 -> 59985 | F39: =G39*H39 -> 566650 | G39: 50 | H39: 11333 | I39: =E39/G39 -> 1199.7 | J39: =D39/G39 -> 9000 | K39: =M39*I39 -> 2399.4 | L39: =I39*N39 -> 58785.3 | M39: =S39+R39 -> 2 | N39: =T39-R39 -> 49 | O39: =U39+H39 -> 22666 | P39: =V39-H39 -> 657314 | R39: 1 | S39: 1 | T39: 50 | U39: 11333 | V39: 668647
A40: 38 | B40: 0 | C40: E. T. OYENIRAN | D40: 330000 | E40: =D40*0.1333 -> 43989 | F40: =G40*H40 -> 373989 | G40: 50 | H40: 7479.78 | I40: =E40/G40 -> 879.78 | J40: =D40/G40 -> 6600 | K40: =M40*I40 -> 879.78 | L40: =I40*N40 -> 43109.22 | M40: 1 | N40: 49 | O40: 7479.78 | P40: =V40-H40 -> 142115.82 | R40: 1 | S40: 1 | T40: 49 | U40: 11333 | V40: 149595.6
...

Sheet Sheet2
A1: =Sheet1!A1 -> MDA'S MOTOR-VEHICLE DEDUCTION RETURNS AS AT APRIL, 2020.
A2: =Sheet1!A2 -> S/N | B2: =Sheet1!B2 -> REF. I.D | C2: =Sheet1!C2 -> STAFF NAME | D2: =Sheet1!D2 -> PRINCIPAL N | E2: =Sheet1!E2 -> INTEREST N | F2: =Sheet1!F2 -> TOTAL LOAN N | G2: =Sheet1!G2 -> NO. OF. INSTL. | H2: =Sheet1!H2 -> MONTHLY DED N | ... Q2: =Sheet1!Q2 -> REMARK
A3: =Sheet1!A3 -> 1 | B3: =Sheet1!B3 -> 0 | C3: =Sheet1!C47 -> A. FALADE | D3: =Sheet1!D47 -> 450000 | E3: =Sheet1!E47 -> 59985 | F3: =Sheet1!F47 -> 509985 | G3: =Sheet1!G47 -> 50 | H3: =Sheet1!H47 -> 10199.7 | I3: =Sheet1!I47 -> 1199.7 | J3: =Sheet1!J47 -> 9000 | ... Q3: =Sheet1!Q47 -> 0
A4: =Sheet1!A4 -> 2 | B4: =Sheet1!B4 -> 0 | C4: =Sheet1!C88 -> ADAMS TAIWO | D4: =Sheet1!D88 -> 150000 | E4: =Sheet1!E88 -> 19995 | F4: =Sheet1!F88 -> 169995 | G4: =Sheet1!G88 -> 50 | H4: =Sheet1!H88 -> 3399.9 | I4: =Sheet1!I88 -> 399.9 | J4: =Sheet1!J88 -> 3000 | ... Q4: =Sheet1!Q88 -> 0
A5: =Sheet1!A5 -> 3 | B5: =Sheet1!B5 -> 0 | C5: =Sheet1!C90 -> ADEBOLA C.E | D5: =Sheet1!D90 -> 500001 | E5: =Sheet1!E90 -> 66650.133 | F5: =Sheet1!F90 -> 424987.5 | G5: =Sheet1!G90 -> 50 | H5: =Sheet1!H90 -> 8499.75 | I5: =Sheet1!I90 -> 1333.0027 | J5: =Sheet1!J90 -> 10000.02 | ... Q5: =Sheet1!Q90 -> 0
A6: =Sheet1!A6 -> 4 | B6: =Sheet1!B6 -> 0 | C6: =Sheet1!C38 -> ADEBOYA O. O. | D6: =Sheet1!D38 -> 450000 | E6: =Sheet1!E38 -> 59985 | F6: =Sheet1!F38 -> 509985 | G6: =Sheet1!G38 -> 50 | H6: =Sheet1!H38 -> 10199.7 | I6: =Sheet1!I38 -> 1199.7 | J6: =Sheet1!J38 -> 9000 | ... Q6: =Sheet1!Q38 -> 0
A7: =Sheet1!A7 -> 5 | B7: =Sheet1!B7 -> 0 | C7: =Sheet1!C131 -> ADEDEJI YISAU | D7: =Sheet1!D131 -> 150000 | E7: =Sheet1!E131 -> 19995 | F7: =Sheet1!F131 -> 169995 | G7: =Sheet1!G131 -> 50 | H7: =Sheet1!H131 -> 3399.9 | I7: =Sheet1!I131 -> 399.9 | J7: =Sheet1!J131 -> 3000 | ... Q7: =Sheet1!Q131 -> 0
A8: =Sheet1!A8 -> 6 | B8: =Sheet1!B8 -> 0 | C8: =Sheet1!C4 -> ADENUGA JUMOKE A. | D8: =Sheet1!D4 -> 600000 | E8: =Sheet1!E4 -> 79980 | F8: =Sheet1!F4 -> 679980 | G8: =Sheet1!G4 -> 50 | H8: =Sheet1!H4 -> 13333 | I8: =Sheet1!I4 -> 1599.6 | J8: =Sheet1!J4 -> 12000 | ... Q8: =Sheet1!Q4 -> 0
A9: =Sheet1!A9 -> 7 | B9: =Sheet1!B9 -> 0 | C9: =Sheet1!C112 -> ADERINTO OLADUUNI | D9: =Sheet1!D112 -> 150000 | E9: =Sheet1!E112 -> 19995 | F9: =Sheet1!F112 -> 169995 | G9: =Sheet1!G112 -> 50 | H9: =Sheet1!H112 -> 3399.9 | I9: =Sheet1!I112 -> 399.9 | J9: =Sheet1!J112 -> 3000 | ... Q9: =Sheet1!Q112 -> 0
A10: =Sheet1!A10 -> 8 | B10: =Sheet1!B10 -> 0 | C10: =Sheet1!C62 -> ADEYEMO G. | D10: =Sheet1!D62 -> 330000 | E10: =Sheet1!E62 -> 43989 | F10: =Sheet1!F62 -> 373989 | G10: =Sheet1!G62 -> 50 | H10: =Sheet1!H62 -> 7479.78 | I10: =Sheet1!I62 -> 879.78 | J10: =Sheet1!J62 -> 6600 | ... Q10: =Sheet1!Q62 -> 0
A11: =Sheet1!A11 -> 9 | B11: =Sheet1!B11 -> 0 | C11: =Sheet1!C63 -> AJALA O. | D11: =Sheet1!D63 -> 330000 | E11: =Sheet1!E63 -> 43989 | F11: =Sheet1!F63 -> 373989 | G11: =Sheet1!G63 -> 50 | H11: =Sheet1!H63 -> 7479.78 | I11: =Sheet1!I63 -> 879.78 | J11: =Sheet1!J63 -> 6600 | ... Q11: =Sheet1!Q63 -> 0
A12: =Sheet1!A12 -> 10 | B12: =Sheet1!B12 -> 0 | C12: =Sheet1!C48 -> AKINPELU ABIODUN | D12: =Sheet1!D48 -> 450000 | E12: =Sheet1!E48 -> 59985 | F12: =Sheet1!F48 -> 0 | G12: =Sheet1!G48 -> 50 | H12: =Sheet1!H48 -> 0 | I12: =Sheet1!I48 -> 1199.7 | J12: =Sheet1!J48 -> 9000 | ... Q12: =Sheet1!Q48 -> 0
A13: =Sheet1!A13 -> 11 | B13: =Sheet1!B13 -> 0 | C13: =Sheet1!C34 -> AKINYELE A. A.O. | D13: =Sheet1!D34 -> 500000 | E13: =Sheet1!E34 -> 66650 | F13: =Sheet1!F34 -> 400000 | G13: =Sheet1!G34 -> 50 | H13: =Sheet1!H34 -> 8000 | I13: =Sheet1!I34 -> 1333 | J13: =Sheet1!J34 -> 10000 | ... Q13: =Sheet1!Q34 -> 0
A14: =Sheet1!A14 -> 12 | B14: =Sheet1!B14 -> 0 | C14: =Sheet1!C5 -> ALABI FUNMILAYO S. | D14: =Sheet1!D5 -> 330000 | E14: =Sheet1!E5 -> 43989 | F14: =Sheet1!F5 -> 373989 | G14: =Sheet1!G5 -> 50 | H14: =Sheet1!H5 -> 7479.78 | I14: =Sheet1!I5 -> 879.78 | J14: =Sheet1!J5 -> 6600 | ... Q14: =Sheet1!Q5 -> 0
A15: =Sheet1!A15 -> 13 | B15: =Sheet1!B15 -> 0 | C15: =Sheet1!C124 -> ARANSI MUKAILA | D15: =Sheet1!D124 -> 150000 | E15: =Sheet1!E124 -> 19995 | F15: =Sheet1!F124 -> 169995 | G15: =Sheet1!G124 -> 50 | H15: =Sheet1!H124 -> 3399.9 | I15: =Sheet1!I124 -> 399.9 | J15: =Sheet1!J124 -> 3000 | ... Q15: =Sheet1!Q124 -> 0
A16: =Sheet1!A16 -> 14 | B16: =Sheet1!B16 -> 0 | C16: =Sheet1!C72 -> AYANNIRAN O. | D16: =Sheet1!D72 -> 330000 | E16: =Sheet1!E72 -> 43989 | F16: =Sheet1!F72 -> 373989 | G16: =Sheet1!G72 -> 50 | H16: =Sheet1!H72 -> 7479.78 | I16: =Sheet1!I72 -> 879.78 | J16: =Sheet1!J72 -> 6600 | ... Q16: =Sheet1!Q72 -> 0
A17: =Sheet1!A17 -> 15 | B17: =Sheet1!B17 -> 0 | C17: =Sheet1!C91 -> E. O. HASSAN | D17: =Sheet1!D91 -> 150000 | E17: =Sheet1!E91 -> 19995 | F17: =Sheet1!F91 -> 169995 | G17: =Sheet1!G91 -> 50 | H17: =Sheet1!H91 -> 3399.9 | I17: =Sheet1!I91 -> 399.9 | J17: =Sheet1!J91 -> 3000 | ... Q17: =Sheet1!Q91 -> 0
A18: =Sheet1!A18 -> 16 | B18: =Sheet1!B18 -> 0 | C18: =Sheet1!C40 -> E. T. OYENIRAN | D18: =Sheet1!D40 -> 330000 | E18: =Sheet1!E40 -> 43989 | F18: =Sheet1!F40 -> 373989 | G18: =Sheet1!G40 -> 50 | H18: =Sheet1!H40 -> 7479.78 | I18: =Sheet1!I40 -> 879.78 | J18: =Sheet1!J40 -> 6600 | ... Q18: =Sheet1!Q40 -> 0
A19: =Sheet1!A19 -> 17 | B19: =Sheet1!B19 -> 0 | C19: =Sheet1!C46 -> ELEGBEDE CHRISTIANAH | D19: =Sheet1!D46 -> 450000 | E19: =Sheet1!E46 -> 59985 | F19: =Sheet1!F46 -> 0 | G19: =Sheet1!G46 -> 50 | H19: =Sheet1!H46 -> 0 | I19: =Sheet1!I46 -> 1199.7 | J19: =Sheet1!J46 -> 9000 | ... Q19: =Sheet1!Q46 -> 0
A20: =Sheet1!A20 -> 18 | B20: =Sheet1!B20 -> 0 | C20: =Sheet1!C65 -> FAGBAYIMU A. G. | D20: =Sheet1!D65 -> 330000 | E20: =Sheet1!E65 -> 43989 | F20: =Sheet1!F65 -> 373989 | G20: =Sheet1!G65 -> 50 | H20: =Sheet1!H65 -> 7479.78 | I20: =Sheet1!I65 -> 879.78 | J20: =Sheet1!J65 -> 6600 | ... Q20: =Sheet1!Q65 -> 0
A21: =Sheet1!A21 -> 19 | B21: =Sheet1!B21 -> 0 | C21: =Sheet1!C26 -> FAMOKUN M.O. | D21: =Sheet1!D26 -> 500000 | E21: =Sheet1!E26 -> 66650 | F21: =Sheet1!F26 -> 509985 | G21: =Sheet1!G26 -> 50 | H21: =Sheet1!H26 -> 10199.7 | I21: =Sheet1!I26 -> 1333 | J21: =Sheet1!J26 -> 10000 | ... Q21: =Sheet1!Q26 -> 0
A22: =Sheet1!A22 -> 20 | B22: =Sheet1!B22 -> 0 | C22: =Sheet1!C68 -> LADEOKIN M. A. | D22: =Sheet1!D68 -> 330000 | E22: =Sheet1!E68 -> 43989 | F22: =Sheet1!F68 -> 373989 | G22: =Sheet1!G68 -> 50 | H22: =Sheet1!H68 -> 7479.78 | I22: =Sheet1!I68 -> 879.78 | J22: =Sheet1!J68 -> 6600 | ... Q22: =Sheet1!Q68 -> 0
A23: =Sheet1!A23 -> 21 | B23: =Sheet1!B23 -> 0 | C23: =Sheet1!C53 -> LAWAL F. A. | D23: =Sheet1!D53 -> 330000 | E23: =Sheet1!E53 -> 43989 | F23: =Sheet1!F53 -> 373989 | G23: =Sheet1!G53 -> 50 | H23: =Sheet1!H53 -> 7479.78 | I23: =Sheet1!I53 -> 879.78 | J23: =Sheet1!J53 -> 6600 | ... Q23: =Sheet1!Q53 -> 0
A24: =Sheet1!A24 -> 22 | B24: =Sheet1!B24 -> 0 | C24: =Sheet1!C60 -> MISS A.D. ADEOYE | D24: =Sheet1!D60 -> 450000 | E24: =Sheet1!E60 -> 59985 | F24: =Sheet1!F60 -> 809985 | G24: =Sheet1!G60 -> 50 | H24: =Sheet1!H60 -> 16199.7 | I24: =Sheet1!I60 -> 1199.7 | J24: =Sheet1!J60 -> 9000 | ... Q24: =Sheet1!Q60 -> 0
A25: =Sheet1!A25 -> 23 | B25: =Sheet1!B25 -> 0 | C25: =Sheet1!C25 -> MISS A.O. ALIMI | D25: =Sheet1!D25 -> 500000 | E25: =Sheet1!E25 -> 66650 | F25: =Sheet1!F25 -> 684985 | G25: =Sheet1!G25 -> 50 | H25: =Sheet1!H25 -> 13699.7 | ... Q25: =Sheet1!Q25 -> 0
A26: =Sheet1!A26 -> 24 | B26: =Sheet1!B26 -> 0 | C26: =Sheet1!C114 -> MISS. ADEMOYE F. M. | D26: =Sheet1!D114 -> 150000 | E26: =Sheet1!E114 -> 19995 | F26: =Sheet1!F114 -> 169995 | G26: =Sheet1!G114 -> 50 | H26: =Sheet1!H114 -> 3399.9 | I26: =Sheet1!I114 -> 399.9 | J26: =Sheet1!J114 -> 3000 | ... Q26: =Sheet1!Q114 -> 0
A27: =Sheet1!A27 -> 25 | B27: =Sheet1!B27 -> 0 | C27: =Sheet1!C137 -> MISS. K. F. KIKIOWO | D27: =Sheet1!D137 -> 450000 | E27: =Sheet1!E137 -> 59985 | F27: =Sheet1!F137 -> 509985 | G27: =Sheet1!G137 -> 50 | H27: =Sheet1!H137 -> 10199.7 | I27: =Sheet1!I137 -> 1199.7 | J27: =Sheet1!J137 -> 9000 | ... Q27: =Sheet1!Q137 -> 0
A28: =Sheet1!A28 -> 26 | B28: =Sheet1!B28 -> 0 | C28: =Sheet1!C19 -> MISS. T. A. ADESOLA | D28: =Sheet1!D19 -> 450000 | E28: =Sheet1!E19 -> 40500 | F28: =Sheet1!F19 -> 478800 | G28: =Sheet1!G19 -> 24 | H28: =Sheet1!H19 -> 19950 | I28: =Sheet1!I19 -> 1687.5 | J28: =Sheet1!J19 -> 18750 | ... Q28: =Sheet1!Q19 -> 0
A29: =Sheet1!A29 -> 27 | B29: =Sheet1!B29 -> 0 | C29: =Sheet1!C94 -> MISS. T. OMOTOSHO | D29: =Sheet1!D94 -> 150000 | E29: =Sheet1!E94 -> 19995 | F29: =Sheet1!F94 -> 169995 | G29: =Sheet1!G94 -> 50 | H29: =Sheet1!H94 -> 3399.9 | I29: =Sheet1!I94 -> 399.9 | J29: =Sheet1!J94 -> 3000 | ... Q29: =Sheet1!Q94 -> 0
A30: =Sheet1!A30 -> 28 | B30: =Sheet1!B30 -> 0 | C30: =Sheet1!C101 -> MORRIS LOLA O. | D30: =Sheet1!D101 -> 150000 | E30: =Sheet1!E101 -> 19995 | F30: =Sheet1!F101 -> 169882.5 | G30: =Sheet1!G101 -> 50 | H30: =Sheet1!H101 -> 3397.65 | I30: =Sheet1!I101 -> 399.9 | J30: =Sheet1!J101 -> 3000 | ... Q30: =Sheet1!Q101 -> 0
A31: =Sheet1!A31 -> 29 | B31: =Sheet1!B31 -> 0 | C31: =Sheet1!C52 -> MR A.A. SODEINDE | D31: =Sheet1!D52 -> 450001 | E31: =Sheet1!E52 -> 59985.133 | F31: =Sheet1!F52 -> 666650 | G31: =Sheet1!G52 -> 50 | H31: =Sheet1!H52 -> 13333 | I31: =Sheet1!I52 -> 1199.7027 | J31: =Sheet1!J52 -> 9000.02 | ... Q31: =Sheet1!Q52 -> 0
A32: =Sheet1!A32 -> 30 | B32: =Sheet1!B32 -> 0 | C32: =Sheet1!C55 -> MR A.A.ADUNMADEHIN | D32: =Sheet1!D55 -> 500000 | E32: =Sheet1!E55 -> 66650 | F32: =Sheet1!F55 -> 424987.5 | G32: =Sheet1!G55 -> 50 | H32: =Sheet1!H55 -> 8499.75 | I32: =Sheet1!I55 -> 1333 | J32: =Sheet1!J55 -> 10000 | ... Q32: =Sheet1!Q55 -> 0
A33: =Sheet1!A33 -> 31 | B33: =Sheet1!B33 -> 0 | C33: =Sheet1!C78 -> MR M.O OLAJIDE | D33: =Sheet1!D78 -> 330000 | E33: =Sheet1!E78 -> 43989 | F33: =Sheet1!F78 -> 373989 | G33: =Sheet1!G78 -> 50 | H33: =Sheet1!H78 -> 7479.78 | I33: =Sheet1!I78 -> 879.78 | J33: =Sheet1!J78 -> 6600 | ... Q33: =Sheet1!Q78 -> 0
A34: =Sheet1!A34 -> 32 | B34: =Sheet1!B34 -> 0 | C34: =Sheet1!C61 -> MR O.E ODUNTAN | D34: =Sheet1!D61 -> 450000 | E34: =Sheet1!E61 -> 59985 | F34: =Sheet1!F61 -> 509985 | G34: =Sheet1!G61 -> 50 | H34: =Sheet1!H61 -> 10199.7 | I34: =Sheet1!I61 -> 1199.7 | J34: =Sheet1!J61 -> 9000 | ... Q34: =Sheet1!Q61 -> 0
A35: =Sheet1!A35 -> 33 | B35: =Sheet1!B35 -> 0 | C35: =Sheet1!C23 -> MR SHOMOYE T.H. | D35: =Sheet1!D23 -> 500000 | E35: =Sheet1!E23 -> 66650 | F35: =Sheet1!F23 -> 509985 | G35: =Sheet1!G23 -> 50 | H35: =Sheet1!H23 -> 10199.7 | I35: =Sheet1!I23 -> 1333 | J35: =Sheet1!J23 -> 10000 | ... Q35: =Sheet1!Q23 -> 0
A36: =Sheet1!A36 -> 34 | B36: =Sheet1!B36 -> 0 | C36: =Sheet1!C121 -> MR T.O. OLOJEDE | D36: =Sheet1!D121 -> 500000 | E36: =Sheet1!E121 -> 66650 | F36: =Sheet1!F121 -> 509985 | G36: =Sheet1!G121 -> 50 | H36: =Sheet1!H121 -> 10199.7 | I36: =Sheet1!I121 -> 1333 | J36: =Sheet1!J121 -> 10000 | ... Q36: =Sheet1!Q121 -> 0
A37: =Sheet1!A37 -> 35 | B37: =Sheet1!B37 -> 0 | C37: =Sheet1!C3 -> MR. A. A. OLADOJA | D37: =Sheet1!D3 -> 500000 | E37: =Sheet1!E3 -> 66650 | F37: =Sheet1!F3 -> 566650 | G37: =Sheet1!G3 -> 50 | H37: =Sheet1!H3 -> 11333 | I37: =Sheet1!I3 -> 1333 | J37: =Sheet1!J3 -> 10000 | ... Q37: =Sheet1!Q3 -> 0
A38: =Sheet1!A38 -> 36 | B38: =Sheet1!B38 -> 0 | C38: =Sheet1!C51 -> MR. A. D. AYOADE | D38: =Sheet1!D51 -> 500000 | E38: =Sheet1!E51 -> 66650 | F38: =Sheet1!F51 -> 566650 | G38: =Sheet1!G51 -> 50 | H38: =Sheet1!H51 -> 11333 | I38: =Sheet1!I51 -> 1333 | J38: =Sheet1!J51 -> 10000 | ... Q38: =Sheet1!Q51 -> 0
A39: =Sheet1!A39 -> 37 | B39: =Sheet1!B39 -> 0 | C39: =Sheet1!C45 -> MR. A. ESAN | D39: =Sheet1!D45 -> 330000 | E39: =Sheet1!E45 -> 43989 | F39: =Sheet1!F45 -> 373989 | G39: =Sheet1!G45 -> 50 | H39: =Sheet1!H45 -> 7479.78 | I39: =Sheet1!I45 -> 879.78 | J39: =Sheet1!J45 -> 6600 | ... Q39: =Sheet1!Q45 -> 0
A40: =Sheet1!A40 -> 38 | B40: =Sheet1!B40 -> 0 | C40: =Sheet1!C64 -> MR. A. L.AWE | D40: =Sheet1!D64 -> 450000 | E40: =Sheet1!E64 -> 59985 | F40: =Sheet1!F64 -> 502322 | G40: =Sheet1!G64 -> 50 | H40: =Sheet1!H64 -> 10046.44 | I40: =Sheet1!I64 -> 1199.7 | J40: =Sheet1!J64 -> 9000 | ... Q40: =Sheet1!Q64 -> 0
...

Sheet Sheet3
A1: staff' Name | B1: Car Loan | C1: S/N | D1: REF. I.D | E1: STAFF NAME | F1: MONTHLY DED N
A2: ODETUNDE A. O. | B2: 11333 | C2: 1 | D2: 0 | E2: MRS. ODETUNDE A. O. | F2: 11333
A3: ADENIRAN ADEWALE O | B3: 10199.7 | C3: 2 | D3: 0 | E3: ADENIRAN ADEWALE O | F3: 10199.7
A4: LAMIDI-HUSSEIN K. O | B4: 10199.7 | C4: 3 | D4: 0 | E4: LAMIDI-HUSSEIN K. O | F4: 10199.7
A5: OLANIYAN OLUYEMI | B5: 10199.7 | C5: 4 | D5: 0 | E5: OLANIYAN OLUYEMI | F5: 10199.7
A6: ADENUGA JUMOKE A. | B6: 7479.78 | C6: 6 | D6: 0 | E6: ADENUGA JUMOKE A. | F6: 7479.78
A7: OLAGUNJU F. O. | B7: 7479.78 | C7: 7 | D7: 0 | E7: OLAGUNJU F. O. | F7: 7479.78
A8: LAWAL ADENIKE M. | B8: 7479.78 | C8: 8 | D8: 0 | E8: LAWAL ADENIKE M. | F8: 7479.78
A9: ABIFARIN TOYIN | B9: 7479.78 | C9: 9 | D9: 0 | E9: ABIFARIN TOYIN | F9: 7479.78
A10: ALABI FUNMILAYO S. | B10: 7479.78 | C10: 10 | D10: 0 | E10: ALABI FUNMILAYO S. | F10: 7479.78
A11: ADEGOKE SAMSON A. | B11: 3399.9 | C11: 11 | D11: 0 | E11: ADEGOKE SAMSON A. | F11: 3399.9
A12: KAREEM SHAKIRUDEEN O. | B12: 1699.95 | C12: 12 | D12: 0 | E12: KAREEM SHAKIRUDEEN O. | F12: 1699.95
A13: AKINDUNNI OLUWAJUMOKE A. | B13: 7479.78 | C13: 13 | D13: 0 | E13: MR. I. J. OLAGUNJU | F13: 7479.78
... A41: BAMIRO M. A. | B41: 11333 | C41: 42 | D41: 0 | E41: BAMIRO M. A. | F41: 11333
A42: ODEMAKINDE B. S. | B42: 11333 | C42: 43 | E42: MRS. B.S. ODEMAKINDE | F42: 11333
A43: ADEBOYA O. O. | B43: 10199.7 | C43: 44 | D43: 0 | E43: ADEBOYA O. O. | F43: 10199.7
A44: FALANA V. O. | B44: 10199.7 | C44: 45 | D44: 0 | E44: FALANA V. O. | F44: 10199.7
A45: YUSUFF F. D. | B45: 7479.78 | C45: 46 | D45: 0 | E45: YUSUFF F. D. | F45: 7479.78
A46: OYENIRAN E. T. | B46: 7479.78 | C46: 47 | D46: 0 | E46: E. T. OYENIRAN | F46: 7479.78
A47: AWEDA R. S. | B47: 7479.78 | C47: 48 | D47: 0 | E47: MR. AWEDA R. S | F47: 7479.78
A48: ADEBAYO O. T. | B48: 7479.78 | C48: 50 | D48: 0 | E48: ADEBAYO O. T. | F48: 7479.78
A49: KAZEEM OLUJOKE | B49: 11333 | C49: 51 | D49: 0 | E49: KAZEEM OLUJOKE | F49: 11333
A50: YUSUFF ADIJAT | B50: 7479.78 | C50: 52 | D50: 0 | E50: OLANIYAN MISTURA B. | F50: 7479.78
A51: OLANIYAN MISTURA B. | B51: 7479.78 | C51: 53 | D51: 0 | E51: MRS. A. YUSUFF | F51: 7479.78
A52: OLUGBILE OPEOLU J. | B52: 13699.7 | C52: 54 | D52: 0 | E52: FOLORUNSO. O. MODUPE | F52: 7479.78
A53: FOLORUNSO. O. MODUPE | B53: 7479.78 | C53: 55 | D53: 0 | E53: ALADE VICTORIA A. | F53: 7479.78
A54: ALADE VICTORIA A. | B54: 7479.78 | C54: 56 | D54: 0 | E54: SALAMI TOYIN O. | F54: 7479.78
... A58: KOLAWOLE RUTH A. | B58: 12979.78 | C58: 60 | D58: 0 | E58: MR. A. ESAN | F58: 7479.78
A59: ADEBISI ALIRAT T. | B59: 3399.9 | C59: 61 | E59: MRS. O. J. ODUGBO | F59: 13699.7
A60: ELEGBEDE CHRISTIANAH | B60: 10199.7 | C60: 62 | D60: 0 | E60: ELEGBEDE CHRISTIANAH | F60: 10199.7
A61: FALADE ADEKUNLE G. | B61: 10199.7 | C61: 63 | D61: 0 | E61: A. FALADE | F61: 10199.7
A62: AKINPELU ABIODUN | B62: 10199.7 | C62: 64 | D62: 0 | E62: AKINPELU ABIODUN | F62: 10199.7
A63: Mrs A. T. Tijani | B63: 7479.78 | C63: 66 | D63: 0 | E63: MRS. A. T. TIJANI | F63: 7479.78
A64: BAKARE A. T. | B64: 15999.75 | C64: 67 | D64: 0 | E64: BAKARE A. T. | F64: 15999.75
A65: LAWAL F. A. | B65: 7479.78 | C65: 68 | D65: 0 | E65: LAWAL F. A. | F65: 7479.78
A66: MRS. M.K. SAFIU OLALERE | B66: 7479.78 | C66: 69 | D66: 0 | E66: SAFIU-OLALERE S, K | F66: 7479.78
A67: ADEGBAYI I. A. | B67: 7479.78 | C67: 70 | D67: 0 | E67: ADEGBAYI I. A. | F67: 7479.78
A68: OSINEYE S. G. | B68: 7479.78 | C68: 71 | D68: 0 | E68: MR. S. G. OSINEYE | F68: 7479.78
A69: OYINLOLA R. T. | B69: 7479.78 | C69: 72 | D69: 0 | E69: OYINLOLA R. T. | F69: 7479.78
A70: TIJANI S. D. | B70: 7479.78 | C70: 73 | D70: 0 | E70: TIJANI S. D. | F70: 7479.78
...

Sheet Sheet4
B1: STAFF NAME | C1: staff' Name | D1: Car Loan | F1: S/N | G1: staff' Name | H1: Car Loan | I1: S/N | J1: STAFF NAME | K1: MONTHLY DED N
A2: 1 | B2: ADETEJU MISBAUDEEN A. | C2: ADETEJU MISBAUDEEN A. | D2: 11333 | F2: 1 | G2: ODETUNDE A. O. | H2: 11333 | I2: 1 | J2: MRS. ODETUNDE A. O. | K2: 11333 | L2: =K2-H2 -> 0
A3: 2 | B3: ADENIRAN ADEWALE O | C3: ADENIRAN ADEWALE O | D3: 10199.7 | F3: 3 | G3: ADENIRAN ADEWALE O | H3: 10199.7 | I3: 3 | J3: ADENIRAN ADEWALE O | K3: 10199.7 | L3: =K3-H3 -> 0
A4: 3 | B4: LAMIDI-HUSSEIN K. O | C4: LAMIDI-HUSSEIN K. O | D4: 10199.7 | F4: 5 | G4: LAMIDI-HUSSEIN K. O | H4: 10199.7 | I4: 4 | J4: LAMIDI-HUSSEIN K. O | K4: 10199.7 | L4: =K4-H4 -> 0
A5: 4 | B5: OLANIYAN OLUYEMI | C5: OLANIYAN OLUYEMI | D5: 10199.7 | F5: 6 | G5: OLANIYAN OLUYEMI | H5: 10199.7 | I5: 5 | J5: OLANIYAN OLUYEMI | K5: 10199.7 | L5: =K5-H5 -> 0
A6: 5 | B6: MORADEYO I. I. | C6: MORADEYO I. I. | D6: 7479.78 | F6: 8 | G6: MORADEYO I. I. | H6: 7479.78 | I6: 6 | J6: MORADEYO I. I. | K6: 7479.78 | L6: =K6-H6 -> 0
A7: 6 | B7: ADENUGA JUMOKE A. | C7: ADENUGA JUMOKE A. | D7: 7479.78 | F7: 9 | G7: ADENUGA JUMOKE A. | H7: 7479.78 | I7: 7 | J7: ADENUGA JUMOKE A. | K7: 7479.78 | L7: =K7-H7 -> 0
A8: 7 | B8: OLAGUNJU F. O. | C8: OLAGUNJU F. O. | D8: 7479.78 | F8: 10 | G8: OLAGUNJU F. O. | H8: 7479.78 | I8: 8 | J8: OLAGUNJU F. O. | K8: 7479.78 | L8: =K8-H8 -> 0
A9: 8 | B9: LAWAL ADENIKE M. | C9: LAWAL ADENIKE M. | D9: 7479.78 | F9: 12 | G9: LAWAL ADENIKE M. | H9: 7479.78 | I9: 9 | J9: LAWAL ADENIKE M. | K9: 7479.78 | L9: =K9-H9 -> 0
A10: 9 | B10: ALABI FUNMILAYO S. | C10: ALABI FUNMILAYO S. | D10: 7479.78 | F10: 15 | G10: ABIFARIN TOYIN | H10: 7479.78 | I10: 10 | J10: ABIFARIN TOYIN | K10: 7479.78 | L10: =K10-H10 -> 0
A11: 10 | B11: ADEGOKE SAMSON A. | C11: ADEGOKE SAMSON A. | D11: 3399.9 | F11: 19 | G11: ALABI FUNMILAYO S. | H11: 7479.78 | I11: 11 | J11: ALABI FUNMILAYO S. | K11: 7479.78 | L11: =K11-H11 -> 0
A12: 11 | B12: KAREEM SHAKIRUDEEN O. | C12: KAREEM SHAKIRUDEEN O. | D12: 1699.95 | F12: 22 | G12: ADEGOKE SAMSON A. | H12: 3399.9 | I12: 12 | J12: ADEGOKE SAMSON A. | K12: 3399.9 | L12: =K12-H12 -> 0
A13: 12 | B13: MR. I. J. OLAGUNJU | C13: AKINDUNNI OLUWAJUMOKE A. | D13: 7479.78 | F13: 25 | G13: KAREEM SHAKIRUDEEN O. | H13: 1699.95 | I13: 13 | J13: KAREEM SHAKIRUDEEN O. | K13: 1699.95 | L13: =K13-H13 -> 0
... A26: 25 | B26: RAJI H. M. | C26: RAJI H. M. | D26: 11333 | F26: 28 | G26: RAJI H. M. | H26: 11333 | I26: 26 | J26: RAJI H. M. | K26: 11333 | L26: =K26-H26 -> 0
A27: 26 | B27: ADEOSUN OLUSOLA O. | D27: 0 | F27: 41 | G27: AJAGUNA M. T. | H27: 10199.7 | I27: 27 | J27: AJAGUNA M. T. | K27: 10199.7 | L27: =K27-H27 -> 0
A28: 27 | B28: SOLE G. A. | C28: SOLE G. A. | D28: 3739.89 | F28: 48 | G28: OLASUNKANMI A. | H28: 10199.7 | I28: 28 | J28: OLASUNKANMI A. | K28: 10199.7 | L28: =K28-H28 -> 0
A29: 28 | B29: AJAGUNA M. T. | C29: AJAGUNA M. T. | D29: 10199.7 | F29: 58 | G29: FAWOLE T. O. | H29: 7479.78 | I29: 29 | J29: FAWOLE TAIWO | K29: 7479.78 | L29: =K29-H29 -> 0
A30: 29 | B30: OLASUNKANMI A. | C30: OLASUNKANMI A. | D30: 10199.7 | F30: 66 | G30: AKINLABI O. M. | H30: 3399.9 | I30: 30 | J30: O. M. AKINLABI | K30: 3399.9 | L30: =K30-H30 -> 0
A31: 30 | B31: FAWOLE TAIWO | C31: FAWOLE T. O. | D31: 7479.78 | F31: 3 | G31: OLUSANYA FLORENCE O. | H31: 10199.7 | I31: 31 | J31: OLUSANYA FLORENCE O. | K31: 10199.7 | L31: =K31-H31 -> 0
A32: 31 | B32: O. M. AKINLABI | C32: AKINLABI O. M. | D32: 3399 | F32: 11 | G32: SALAMI W. A. | H32: 7479.78 | I32: 32 | J32: SALAMI W. A. | K32: 7479.78 | L32: =K32-H32 -> 0
A33: 32 | B33: OLUSANYA FLORENCE O. | C33: OLUSANYA FLORENCE O. | D33: 10199.7 | F33: 12 | G33: SAMUEL PATIENCE C. | H33: 7479.78 | I33: 33 | J33: SAMUEL PATIENCE C. | K33: 7479.78 | L33: =K33-H33 -> 0
A34: 33 | B34: OLANIYI TITILAYO | D34: 0 | F34: 13 | G34: ADESAMI MODUPELOLA M. | H34: 7479.78 | I34: 34 | J34: ADESAMI MODUPELOLA M. | K34: 7479.78 | L34: =K34-H34 -> 0
A35: 34 | B35: SALAMI W. A. | C35: SALAMI W. A. | D35: 7479.78 | F35: 16 | G35: OLAITAN LANRE IYIOLA | H35: 7479.78 | I35: 35 | J35: OLAITAN LANRE IYIOLA | K35: 7479.78 | L35: =K35-H35 -> 0
A36: 35 | B36: SAMUEL PATIENCE C. | C36: SAMUEL PATIENCE C. | D36: 7479.78 | F36: 17 | G36: OLAWORE MICHEAL F. | H36: 7479.78 | I36: 36 | J36: OLAWORE MICHEAL F. | K36: 7479.78 | L36: =K36-H36 -> 0
A37: 36 | B37: ADESAMI MODUPELOLA M. | C37: ADESAMI MODUPELOLA M. | D37: 7479.78 | F37: 20 | G37: AFOLABI MARY A. | H37: 3399.9 | I37: 37 | J37: AFOLABI MARY A. | K37: 3399.9 | L37: =K37-H37 -> 0
A38: 37 | B38: OLAITAN LANRE IYIOLA | C38: OLAITAN LANRE IYIOLA | D38: 7479.78 | F38: 28 | G38: MOJEED T. A | H38: 3399.9 | I38: 38 | J38: MRS. T. A. MOJEED | K38: 3399.9 | L38: =K38-H38 -> 0
A39: 38 | B39: OLAWORE MICHEAL F. | C39: OLAWORE MICHEAL F. | D39: 7479.78 | F39: 29 | G39: MOSOMI OLUWAFUNKE | H39: 3399.9 | I39: 39 | J39: MOSOMI OLUWAFUNKE | K39: 3399.9 | L39: =K39-H39 -> 0
A40: 39 | B40: AFOLABI MARY A. | C40: AFOLABI MARY A. | D40: 3399.9 | F40: 1 | G40: OLATUNJI-DANIEL A. A. | H40: 11333 | I40: 40 | J40: OLATUNJI-DANIEL A. A. | K40: 11333 | L40: =K40-H40 -> 0
A41: 40 | B41: MRS. T. A. MOJEED | C41: MOJEED T. A | D41: 3399.9 | F41: 5 | G41: AKINYELE A. A.,O. | H41: 11333 | I41: 41 | J41: AKINYELE A. A.,O. | K41: 11333 | L41: =K41-H41 -> 0
A42: 41 | B42: MOSOMI OLUWAFUNKE | C42: MOSOMI OLUWAFUNKE | D42: 3399.9 | F42: 10 | G42: EBELOKU-MUSTAPHA R. A. | H42: 11333 | I42: 42 | J42: EBELOKU-MUSTAPHA R. A. | K42: 11333 | L42: =K42-H42 -> 0
A43: 42 | B43: ONIBIYO ABIMBOLA. A. | C43: ONIBIYO ABIMBOLA. A. | D43: 1699.95 | F43: 11 | G43: BAMIRO M. A. | H43: 11333 | I43: 43 | J43: BAMIRO M. A. | K43: 11333 | L43: =K43-H43 -> 0
A44: 43 | B44: OLATUNJI-DANIEL A. A. | C44: OLATUNJI-DANIEL A. A. | D44: 11333 | F44: 12 | G44: ODEMAKINDE B. S. | H44: 11333 | I44: 44 | J44: MRS. B.S. ODEMAKINDE | K44: 11333 | L44: =K44-H44 -> 0
A45: 44 | B45: ADIO M. O. | C45: ADIO M. O. | D45: 11333 | F45: 14 | G45: ADEBOYA O. O. | H45: 10199.7 | I45: 45 | J45: ADEBOYA O. O. | K45: 10199.7 | L45: =K45-H45 -> 0
A46: 45 | B46: OGUNRIN O. A. | C46: OGUNRIN O. A. | D46: 5666.5 | F46: 16 | G46: FALANA V. O. | H46: 10199.7 | I46: 46 | J46: FALANA V. O. | K46: 10199.7 | L46: =K46-H46 -> 0
... A70: 69 | B70: BAKARE A. T. | C70: BAKARE A. T. | D70: 16999.5 | F70: 11 | G70: ADEGBAYI I. A. | H70: 7479.78 | I70: 70 | J70: ADEGBAYI I. A. | K70: 7479.78 | L70: =K70-H70 -> 0
A71: 70 | B71: Mr A. A. Ipaye | D71: 0 | F71: 13 | G71: OSINEYE S. G. | H71: 7479.78 | I71: 71 | J71: MR. S. G. OSINEYE | K71: 7479.78 | L71: =K71-H71 -> 0
A72: 71 | B72: ADEGBAYI I. A. | C72: ADEGBAYI I. A. | D72: 7479.78 | F72: 14 | G72: OYINLOLA R. T. | H72: 7479.78 | I72: 72 | J72: OYINLOLA R. T. | K72: 7479.78 | L72: =K72-H72 -> 0
A73: 72 | B73: OLAGUNJU K. A. | C73: OLAGUNJU K. A. | D73: 7479.78 | F73: 15 | G73: TIJANI S. D. | H73: 7479.78 | I73: 73 | J73: TIJANI S. D. | K73: 7479.78 | L73: =K73-H73 -> 0
A74: 73 | B74: OYINLOLA R. T. | C74: OYINLOLA R. T. | D74: 7479.78 | F74: 18 | G74: ALAO O. O. | H74: 7479.78 | I74: 74 | J74: MR. O. O. ALAO | K74: 7479.78 | L74: =K74-H74 -> 0
A75: 74 | B75: TIJANI S. D. | C75: TIJANI S. D. | D75: 7479.78 | F75: 19 | G75: ONI OLUWABUNMI E. | H75: 7479.78 | I75: 75 | J75: ONI OLUWABUNMI E. | K75: 7479.78 | L75: =K75-H75 -> 0
...

Sheet Sheet5
A1: 3 | B1: ADENIRAN ADEWALE O | C1: 10199.7 | D1: ADENIRAN ADEWALE O | E1: 10199.7
A2: 5 | B2: LAMIDI-HUSSEIN K. O | C2: 10199.7 | D2: LAMIDI-HUSSEIN K. O | E2: 10199.7
A3: 6 | B3: OLANIYAN OLUYEMI | C3: 10199.7 | D3: OLANIYAN OLUYEMI | E3: 10199.7
A4: 7 | B4: AKANBI A. G. | C4: 3739.89 | D4: AKANBI A. G. | E4: 3739.89
A5: 8 | B5: MORADEYO I. I. | C5: 7479.78 | D5: MORADEYO I. I. | E5: 7479.78
A6: 9 | B6: ADENUGA JUMOKE A. | C6: 7479.78 | D6: ADENUGA JUMOKE A. | E6: 7479.78
A7: 10 | B7: OLAGUNJU F. O. | C7: 7479.78 | D7: OLAGUNJU F. O. | E7: 7479.78
A8: 11 | B8: ABODERIN OLUSEYE | C8: 3739.89 | D8: ABODERIN OLUSEYE | E8: 3739.89
A9: 12 | B9: LAWAL ADENIKE M. | C9: 7479.78 | D9: LAWAL ADENIKE M. | E9: 7479.78
A10: 19 | B10: KAZALI KUDIRAT B. | C10: 3739.89 | D10: KAZALI KUDIRAT B. | E10: 3739.89
A11: 20 | B11: ALABI FUNMILAYO S. | C11: 7479.78 | D11: ALABI FUNMILAYO S. | E11: 7479.78
A12: 23 | B12: ADEGOKE SAMSON A. | C12: 3399.9 | D12: ADEGOKE SAMSON A. | E12: 3399.9
... A43: 50 | B43: AKANDE OLUWATOYIN A. | C43: 1699.95 | D43: AKANDE OLUWATOYIN A. | E43: 1699.95
D44: KOLAPO TAWA A. | E44: 10199.7
A45: 5 | B45: OLUSANYA FLORENCE O. | C45: 10199.7 | D45: OLUSANYA FLORENCE O. | E45: 10199.7
A46: 7 | B46: ODEJIDE HELEN K. | C46: 7479.78 | D46: ODEJIDE HELEN K. | E46: 7479.78
A47: 8 | B47: ADEOSUN KEHINDE | C47: 3739.89 | D47: ADEOSUN KEHINDE | E47: 3739.89
A48: 9 | B48: AREMU OLAYEMI MARY | C48: 3739.89 | D48: AREMU OLAYEMI MARY | E48: 3739.89
A49: 13 | B49: OLANIYI TITILAYO | C49: 3739.89 | D49: OLANIYI TITILAYO | E49: 3739.89
A50: 14 | B50: SALAMI W. A. | C50: 7479.78 | D50: SALAMI W. A. | E50: 7479.78
A51: 15 | B51: SAMUEL PATIENCE C. | C51: 7479.78 | D51: SAMUEL PATIENCE C. | E51: 7479.78
A52: 16 | B52: ADESAMI MODUPELOLA M. | C52: 7479.78 | D52: ADESAMI MODUPELOLA M. | E52: 7479.78
A53: 19 | B53: OLAITAN LANRE IYIOLA | C53: 7479.78 | D53: OLAITAN LANRE IYIOLA | E53: 7479.78
A54: 20 | B54: OLAWORE MICHEAL F. | C54: 7479.78 | D54: OLAWORE MICHEAL F. | E54: 7479.78
A55: 21 | B55: ADEJUMO TAIWO O. | C55: 3739.89 | D55: ADEJUMO TAIWO O. | E55: 3739.89
A56: 24 | B56: AFOLABI MARY A. | C56: 3399.9 | D56: AFOLABI MARY A. | E56: 3399.9
... A101: 7 | B101: LAWAL TIRIMISIYU A. | C101: 11333 | D101: MR. T. A. LAWAL | E101: 11333
D102: BAKARE A. T. | E102: 0
A103: 5 | B103: HAMMED S. O. | C103: 3739.89 | D103: HAMMED S. O. | E103: 3739.89
A104: 6 | B104: Mr A. A. Ipaye | C104: 3739.89 | D104: Mr A. A. Ipaye | E104: 3739.89
A105: 9 | B105: ODUNTAN O. E. | C105: 3739.89 | D105: ODUNTAN O. E. | E105: 3739.89
A106: 11 | B106: ISIAKA S. | C106: 3739.89 | D106: ISIAKA S. | E106: 3739.89
A107: 12 | B107: ADEGBAYI I. A. | C107: 7479.78 | D107: ADEGBAYI I. A. | E107: 7479.78
A108: 13 | B108: BAMIDELE A. A. | C108: 3739.89 | D108: BAMIDELE A. A. | E108: 3739.89
A109: 14 | B109: OLAGUNJU K. A. | C109: 7479.78 | D109: OLAGUNJU K. A. | E109: 7479.78
A110: 16 | B110: OYINLOLA R. T. | C110: 7479.78 | D110: OYINLOLA R. T. | E110: 7479.78
A111: 17 | B111: TIJANI S. D. | C111: 7479.78 | D111: TIJANI S. D. | E111: 7479.78
A112: 18 | B112: YUSUFF K. A. | C112: 3739.89 | D112: YUSUFF K. A. | E112: 3739.89
A113: 20 | B113: ALAO O. O. | C113: 7479.78
A114: 21 | B114: ONI OLUWABUNMI E. | C114: 7479.78 | D114: ONI OLUWABUNMI E. | E114: 7479.78
...

Sheet Sheet6
A1: OLABAMIJI ADETUTU | B1: 330000 | C1: =B1*0.1333 -> 43989 | D1: =E1*F1 -> 373989 | E1: 50 | F1: 7479.78 | G1: *
A2: MR. O. OSUNLANA | B2: 330000 | C2: =B2*0.1333 -> 43989 | D2: =E2*F2 -> 373989 | E2: 50 | F2: 7479.78 | G2: *
A3: OKETOKI A.F | B3: 150000 | C3: =B3*0.1333 -> 19995 | D3: =E3*F3 -> 169997.5 | E3: 50 | F3: 3399.95 | G3: *
A4: BALOGUN ABIBAT A. | B4: 150000 | C4: =B4*0.1333 -> 19995 | D4: =E4*F4 -> 339990 | E4: 50 | F4: 6799.8 | G4: *
A5: MORRIS LOLA O. | B5: 150000 | C5: =B5*0.1333 -> 19995 | D5: =E5*F5 -> 169997.5 | E5: 50 | F5: 3399.95 | G5: *
A6: MR. SAHEED G. ABIOYE | B6: 330000 | C6: =B6*0.1333 -> 43989 | D6: =E6*F6 -> 373989 | E6: 50 | F6: 7479.78 | G6: *
A7: MRS. O. Y. ALUKO | B7: 150000 | C7: =B7*0.1333 -> 19995 | D7: =E7*F7 -> 169995 | E7: 50 | F7: 3399.9 | G7: *
A8: MRS. D. O. ABODUNDE | B8: 150000 | C8: =B8*0.1333 -> 19995 | D8: =E8*F8 -> 169995 | E8: 50 | F8: 3399.9 | G8: *
A9: MRS. R. A. OWOADE | B9: 330000 | C9: =B9*0.1333 -> 43989 | D9: =E9*F9 -> 373989 | E9: 50 | F9: 7479.78 | G9: *
A10: MRS. J. A. OWOADE | B10: 330000 | C10: =B10*0.1333 -> 43989 | D10: =E10*F10 -> 373989 | E10: 50 | F10: 7479.78 | G10: *
A11: MR. A. O. ADEFI | B11: 150000 | C11: =B11*0.1333 -> 19995 | D11: =E11*F11 -> 169995 | E11: 50 | F11: 3399.9 | G11: *
A12: MRS. Y. S. OGUNSIJI | B12: 150000 | C12: =B12*0.1333 -> 19995 | D12: =E12*F12 -> 169995 | E12: 50 | F12: 3399.9 | G12: *
... A20: MISS. ADEMOYE MARIAM F. | B20: 150000 | C20: =B20*0.1333 -> 19995 | D20: =E20*F20 -> 169995 | E20: 50 | F20: 3399.9 | G20: *
F21: =SUM(F1:F20) -> 110507.06
F22: 107107.16
F23: =F21-F22 -> 3399.9

Sheet Sheet7
A2: S/N | B2: REF. I.D | C2: STAFF NAME | D2: MONTHLY DED N | E2: S/N | F2: staff' Name | G2: Car Loan
A3: 1 | B3: 0 | C3: MRS. ODETUNDE A. O. | D3: 11333 | E3: 1 | F3: ODETUNDE A. O. | G3: 11333
A4: 2 | B4: 0 | C4: LAMIDI-HUSSEIN K. O | D4: 10199.7 | E4: 3 | F4: LAMIDI-HUSSEIN K. O | G4: 10199.7
A5: 4 | B5: 0 | C5: ADENUGA JUMOKE A. | D5: 7479.78 | E5: 6 | F5: ADENUGA JUMOKE A. | G5: 7479.78
A6: 5 | B6: 0 | C6: MR. OLUSEYE ABODERIN | D6: 10199.7 | E6: 7 | F6: ABODERIN OLUSEYE | G6: 10199.7
A7: 6 | B7: 0 | C7: LAWAL ADENIKE M. | D7: 10000 | E7: 8 | F7: LAWAL ADENIKE M. | G7: 10000
A8: 7 | B8: 0 | C8: ABIFARIN TOYIN | D8: 7479.78 | E8: 11 | F8: ABIFARIN TOYIN | G8: 7479.78
A9: 8 | B9: 0 | C9: ALABI FUNMILAYO S. | D9: 7479.78 | E9: 15 | F9: ALABI FUNMILAYO S. | G9: 7479.78
A10: 9 | B10: 0 | C10: AKINDUNNI OLUWAJUMOKE A. | D10: 7479.78 | E10: 4 | F10: AKINDUNNI OLUWAJUMOKE A. | G10: 7479.78
A11: 10 | B11: 0 | C11: MR. I. J. OLAGUNJU | D11: 7479.78 | E11: 7 | F11: OLAGUNJU IBUKUN J. | G11: 7479.78
A12: 11 | B12: 0 | C12: BABALOLA AINA O. | D12: 3399.9 | E12: 13 | F12: BABALOLA AINA O. | G12: 3399.9
A13: 12 | B13: 0 | C13: IWUNOR OLUBISI O. | D13: 7479.78 | E13: 3 | F13: IWUNOR OLUBISI O. | G13: 7479.78
A14: 13 | B14: 0 | C14: OLAGUNJU ESTHER A. | D14: 7479.78 | E14: 4 | F14: OLAGUNJU ESTHER A. | G14: 7479.78
... A33: 32 | B33: 0 | C33: OLAITAN LANRE IYIOLA | D33: 7479.78 | E33: 12 | F33: OLAITAN LANRE IYIOLA | G33: 7479.78
A34: 33 | C34: OLAWORE MICHEAL F. | D34: 7479.78 | E34: 13 | F34: OLAWORE MICHEAL F. | G34: 7479.78
A35: 34 | B35: 0 | C35: MRS. TAIWO O. ADEJUMO | D35: 7479.78 | E35: 14 | F35: ADEJUMO TAIWO O. | G35: 7479.78
A36: 35 | B36: 0 | C36: AFOLABI MARY A. | D36: 3399.9 | E36: 16 | F36: AFOLABI MARY A. | G36: 3399.9
A37: 36 | B37: 0 | C37: MRS. T. A. MOJEED | D37: 3399.9 | E37: 22 | F37: MOJEED T. A | G37: 3399.9
A38: 37 | B38: 0 | C38: MOSOMI OLUWAFUNKE | D38: 3399.9 | E38: 23 | F38: MOSOMI OLUWAFUNKE | G38: 3399.9
A39: 38 | B39: 0 | C39: AKINYELE A. A.,O. | D39: 11333 | E39: 4 | F39: AKINYELE A. A.,O. | G39: 11333
A40: 39 | C40: MRS. B.S. ODEMAKINDE | D40: 11333 | E40: 11 | F40: ODEMAKINDE B. S. | G40: 11333
A41: 40 | C41: MR. MARTINS K. O. | D41: 10199.7 | E41: 12 | F41: MARTINS K. O. | G41: 10199.7
A42: 41 | B42: 0 | C42: ADEBOYA O. O. | D42: 10199.7 | E42: 13 | F42: ADEBOYA O. O. | G42: 10199.7
A43: 42 | B43: 0 | C43: FALANA V. O. | D43: 10199.7 | E43: 15 | F43: FALANA V. O. | G43: 10199.7
A44: 43 | B44: 0 | C44: E. T. OYENIRAN | D44: 7479.78 | E44: 19 | F44: OYENIRAN E. T. | G44: 7479.78
A45: 44 | B45: 0 | C45: OLANIYAN O. | D45: 7479.78 | E45: 22 | F45: MR. O.OLANIYAN | G45: 7479.78
A46: 45 | B46: 0 | C46: ADEBAYO O. T. | D46: 7479.78 | E46: 24 | F46: ADEBAYO O. T. | G46: 7479.78
A47: 46 | B47: 0 | C47: KAZEEM OLUJOKE | D47: 11333 | E47: 1 | F47: KAZEEM OLUJOKE | G47: 11333
A48: 47 | B48: 0 | C48: MRS. A. YUSUFF | D48: 7479.78 | E48: 2 | F48: YUSUFF ADIJAT | G48: 7479.78
A49: 48 | B49: 0 | C49: OLANIYAN MISTURA B. | D49: 7479.78 | E49: 4 | F49: OLANIYAN MISTURA B. | G49: 7479.78
A50: 49 | B50: 0 | C50: FOLORUNSO. O. MODUPE | D50: 7479.78 | E50: 2 | F50: FOLORUNSO. O. MODUPE | G50: 7479.78
A51: 50 | B51: 0 | C51: ALADE VICTORIA A. | D51: 7479.78 | E51: 5 | F51: ALADE VICTORIA A. | G51: 7479.78
A52: 51 | B52: 0 | C52: SALAMI TOYIN O. | D52: 7479.78 | E52: 6 | F52: SALAMI TOYIN O. | G52: 7479.78
A53: 52 | B53: 0 | C53: MR. A. ESAN | D53: 7479.78 | E53: 7 | F53: ESAN ADENRELE | G53: 7479.78
... A59: 58 | B59: 0 | C59: MR. S. T. AMOO | D59: 10199.7 | E59: 14 | F59: AMOO S.T | G59: 10199.7
A60: 59 | C60: MRS. A. T. TIJANI | D60: 7479.78 | E60: 18 | F60: Mrs A. T. Tijani | G60: 7479.78
A61: 60 | B61: 0 | C61: BAKARE A. T. | D61: 15999.75 | E61: 2 | F61: BAKARE A. T. | G61: 15999.75
A62: 61 | B62: 0 | C62: LAWAL F. A. | D62: 7479.78 | E62: 6 | F62: LAWAL F. A. | G62: 7479.78
A63: 62 | B63: 0 | C63: SAFIU-OLALERE S, K | D63: 7479.78 | E63: 9 | F63: MRS. M.K. SAFIU OLALERE | G63: 7479.78
A64: 63 | B64: 0 | C64: ADEGBAYI I. A. | D64: 7479.78 | E64: 11 | F64: ADEGBAYI I. A. | G64: 7479.78
...
